Workbook

Sheet MED 01
D1: OBRA: FKR-018 - RIL
D2: FORNECEDOR: | G2: MBRUM CONSTRUÇÕES LTDA
D3: PLANILHA DE MEDIÇÃO DE SERVIÇOS - CONTRATUAL
B5: =G2 -> MBRUM CONSTRUÇÕES LTDA | H5: PERÍODO MEDIÇÃO | K5: BM-Nº | N5: 1
B6: =D1 -> OBRA: FKR-018 - RIL | H6: DE 09/02/2026 a 23/02/2026 | K6: VENCIMENTO | N6: 28/02/2026
A7: ITEM | B7: 1BN | C7: CONTRATUAL | H7: ESTA MEDIÇÃO | K7: ACUMULADO ATUAL | M7: SALDO À MEDIR
C8: % | D8: Qtde | G8: TOTAL CONTRATUAL | H8: Qtde | J8: TOTAL DESTA MEDIÇÃO | K8: Qtde | L8: TOTAL ACUMULADO ANTERIOR | M8: SALDO | N8: %
E9: VALOR UNITÁRIO | F9: VALOR TOTAL | I9: VALOR UNITÁRIO
A10: 1 | B10: DIÁRIA DE SERVENTE | C10: DIA | D10: 1 | E10: 297 | G10: =E10 -> 297 | H10: =Auxiliar!F21 -> 33 | I10: =+E10 -> 297 | J10: =+I10*H10 -> 9801 | K10: =+H10 -> 33 | L10: =+J10 -> 9801
A11: 2 | B11: DIÁRIA DE MEIO-OFICIAL | C11: DIA | D11: 1 | E11: 407 | G11: =E11 -> 407 | H11: =Auxiliar!E21 -> 8 | I11: =+E11 -> 407 | J11: =+I11*H11 -> 3256 | K11: =+H11 -> 8 | L11: =+J11 -> 3256
A12: 3 | B12: DIÁRIA DE PEDREIRO | C12: DIA | D12: 1 | E12: 438 | G12: =E12 -> 438 | H12: =Auxiliar!C21 -> 35 | I12: =+E12 -> 438 | J12: =+I12*H12 -> 15330 | K12: =+H12 -> 35 | L12: =+J12 -> 15330
G14: =SUM(G10:G12) -> 1142 | J14: =SUM(J10:J12) -> 28387 | K14: T. ACUM. ATUAL | M14: =+SUM(L10:L12) -> 28387
B16: FATURAMENTO DIRETO | G16: =J14 -> 28387 | H16: RETENÇÃO CONTRATUAL - 5% | K16: RETENÇÃO IMPOSTOS
A17: ITEM | B17: FORNECEDOR/PRODUTO | C17: NF/QUANTIDADE | G17: VALOR | H17: ACUMULADA, INC. ESTA | J17: =+J23 -> 1419.35
A18: 1
A19: 2
A20: 3
A21: 4
A22: 5
E23: VALOR FAT. DIRETO | G23: =+SUM(E18:G22) -> 0 | H23: VALOR RETENÇÃO TÉCNICA | J23: =G25*0.05 -> 1419.35 | K23: VALOR RETENÇÃO IMPOSTOS | M23: =M21 -> 0
B25: FARKAS CONSTRUTORA | E25: VALOR - FAT. DIRETO | G25: =G16-G23 -> 28387 | H25: VALOR - RETENÇÃO | J25: =G25-J23 -> 26967.65 | K25: VALOR NF A SER EMITIDA | M25: =+J25-M23 -> 26967.65

Sheet MED 02
D1: OBRA: FKR-018 - RIL
D2: FORNECEDOR: | G2: MBRUM CONSTRUÇÕES LTDA
D3: PLANILHA DE MEDIÇÃO DE SERVIÇOS - CONTRATUAL
B5: =G2 -> MBRUM CONSTRUÇÕES LTDA | H5: PERÍODO MEDIÇÃO | K5: BM-Nº | N5: 1
B6: =D1 -> OBRA: FKR-018 - RIL | H6: DE 09/02/2026 a 23/02/2026 | K6: VENCIMENTO | N6: 28/02/2026
A7: ITEM | B7: 1BN | C7: CONTRATUAL | H7: ESTA MEDIÇÃO | K7: ACUMULADO ATUAL | M7: SALDO À MEDIR
C8: % | D8: Qtde | E8: VALOR UNITÁRIO | F8: VALOR TOTAL | G8: TOTAL CONTRATUAL | H8: Qtde | I8: VALOR UNITÁRIO | J8: TOTAL DESTA MEDIÇÃO | K8: Qtde | L8: TOTAL ACUMULADO ANTERIOR | M8: SALDO | N8: %
A10: 1 | B10: DIÁRIA DE SERVENTE | C10: DIA | D10: 1 | E10: 323.73 | G10: =E10 -> 323.73 | H10: =Auxiliar!F36 -> 52 | I10: =+E10 -> 323.73 | J10: =+I10*H10 -> 16833.96 | K10: =+H10 -> 52 | L10: =+J10 -> 16833.96
A11: 2 | B11: DIÁRIA DE MEIO-OFICIAL | C11: DIA | D11: 1 | E11: 443.63 | G11: =E11 -> 443.63 | H11: =Auxiliar!E36 -> 16 | I11: =+E11 -> 443.63 | J11: =+I11*H11 -> 7098.08 | K11: =+H11 -> 16 | L11: =+J11 -> 7098.08
A12: 3 | B12: DIÁRIA DE PEDREIRO | C12: DIA | D12: 1 | E12: 477.42 | G12: =E12 -> 477.42 | H12: =Auxiliar!C36 -> 47 | I12: =+E12 -> 477.42 | J12: =+I12*H12 -> 22438.74 | K12: =+H12 -> 47 | L12: =+J12 -> 22438.74
G13: =E13*D13 -> 0 | I13: =+E13 -> 0 | J13: =+I13*H13 -> 0
G14: =SUM(G10:G12) -> 1244.78 | J14: =SUM(J10:J13) -> 46370.78 | K14: T. ACUM. ATUAL | M14: =+SUM(L10:L12) -> 46370.78
B16: FATURAMENTO DIRETO | G16: =J14 -> 46370.78 | H16: RETENÇÃO CONTRATUAL - 5% | K16: RETENÇÃO IMPOSTOS
A17: ITEM | B17: FORNECEDOR/PRODUTO | C17: NF/QUANTIDADE | G17: VALOR | H17: ACUMULADA, INC. ESTA | J17: =+J23+'MED 01'!J17 -> 3726.149
A18: 1 | B18: CAPA | C18: 5 | E18: =C18*23 -> 115
A19: 2 | B19: LUVA | C19: 10 | E19: =C19*9.38 -> 93.8
A20: 3 | B20: OCULOS | C20: 8 | E20: =C20*3.25 -> 26
A21: 4
A22: 5
E23: VALOR FAT. DIRETO | G23: =+SUM(E18:G22) -> 234.8 | H23: VALOR RETENÇÃO TÉCNICA | J23: =G25*0.05 -> 2306.799 | K23: VALOR RETENÇÃO IMPOSTOS | M23: =M21 -> 0
B25: FARKAS CONSTRUTORA | E25: VALOR - FAT. DIRETO | G25: =G16-G23 -> 46135.98 | H25: VALOR - RETENÇÃO | J25: =G25-J23 -> 43829.181 | K25: VALOR NF A SER EMITIDA | M25: =+J25-M23 -> 43829.181
A26: OBS: MEDIÇÃO 01 FALTOU O VALOR DE 3.149,37

Sheet MED 03
D1: OBRA: FKR-018 - RIL
D2: FORNECEDOR: | G2: MBRUM CONSTRUÇÕES LTDA
D3: PLANILHA DE MEDIÇÃO DE SERVIÇOS - CONTRATUAL
B5: =G2 -> MBRUM CONSTRUÇÕES LTDA | H5: PERÍODO MEDIÇÃO | K5: BM-Nº | N5: 3
B6: =D1 -> OBRA: FKR-018 - RIL | H6: DE 09/03/2026 a 23/03/2026 | K6: VENCIMENTO | N6: 30/03/2026
A7: ITEM | B7: 1BN | C7: CONTRATUAL | H7: ESTA MEDIÇÃO | K7: ACUMULADO ATUAL | M7: SALDO À MEDIR
C8: % | D8: Qtde | E8: VALOR UNITÁRIO | F8: VALOR TOTAL | G8: TOTAL CONTRATUAL | H8: Qtde | I8: VALOR UNITÁRIO | J8: TOTAL DESTA MEDIÇÃO | K8: Qtde | L8: TOTAL ACUMULADO ANTERIOR | M8: SALDO | N8: %
A10: 1 | B10: DIÁRIA DE SERVENTE | C10: DIA | D10: 1 | E10: 323.73 | G10: =E10 -> 323.73 | H10: =Auxiliar!F52 -> 66 | I10: =+E10 -> 323.73 | J10: =+I10*H10 -> 21366.18 | K10: =+H10 -> 66 | L10: =+J10 -> 21366.18
A11: 2 | B11: DIÁRIA DE MEIO-OFICIAL | C11: DIA | D11: 1 | E11: 443.63 | G11: =E11 -> 443.63 | H11: =Auxiliar!E52 -> 11 | I11: =+E11 -> 443.63 | J11: =+I11*H11 -> 4879.93 | K11: =+H11 -> 11 | L11: =+J11 -> 4879.93
A12: 3 | B12: DIÁRIA DE PEDREIRO | C12: DIA | D12: 1 | E12: 477.42 | G12: =E12 -> 477.42 | H12: =Auxiliar!C52 -> 44 | I12: =+E12 -> 477.42 | J12: =+I12*H12 -> 21006.48 | K12: =+H12 -> 44 | L12: =+J12 -> 21006.48
G13: =E13*D13 -> 0 | I13: =+E13 -> 0 | J13: =+I13*H13 -> 0
G14: =SUM(G10:G12) -> 1244.78 | J14: =SUM(J10:J13) -> 47252.59 | K14: T. ACUM. ATUAL | M14: =+SUM(L10:L12) -> 47252.59
B16: FATURAMENTO DIRETO | G16: =J14 -> 47252.59 | H16: RETENÇÃO CONTRATUAL - 5% | K16: RETENÇÃO IMPOSTOS
A17: ITEM | B17: FORNECEDOR/PRODUTO | C17: NF/QUANTIDADE | G17: VALOR | H17: ACUMULADA, INC. ESTA | J17: =+J22+'MED 02'!J17 -> 6075.4695
A18: 1 | B18: LUVA | C18: 11 | E18: =9.38*C18 -> 103.18
A19: 2 | B19: OCULOS | C19: 6 | E19: =6.5*C19 -> 39
A20: 3 | B20: BOTA | C20: 2 | E20: =62*C20 -> 124
A21: 4
E22: VALOR FAT. DIRETO | G22: =+SUM(E18:G21) -> 266.18 | H22: VALOR RETENÇÃO TÉCNICA | J22: =G24*0.05 -> 2349.3205 | K22: VALOR RETENÇÃO IMPOSTOS | M22: =M20 -> 0
B24: FARKAS CONSTRUTORA | E24: VALOR - FAT. DIRETO | G24: =G16-G22 -> 46986.41 | H24: VALOR - RETENÇÃO | J24: =G24-J22 -> 44637.089 | K24: VALOR NF A SER EMITIDA | M24: =+J24-M22 -> 44637.089

Sheet MED 04
D1: OBRA: FKR-018 - RIL
D2: FORNECEDOR: | G2: MBRUM CONSTRUÇÕES LTDA
D3: PLANILHA DE MEDIÇÃO DE SERVIÇOS - CONTRATUAL
B5: =G2 -> MBRUM CONSTRUÇÕES LTDA | H5: PERÍODO MEDIÇÃO | K5: BM-Nº | N5: 4
B6: =D1 -> OBRA: FKR-018 - RIL | H6: DE 24/03/2026 a 07/04/2026 | K6: VENCIMENTO | N6: 15/04/2026
A7: ITEM | B7: 1BN | C7: CONTRATUAL | H7: ESTA MEDIÇÃO | K7: ACUMULADO ATUAL | M7: SALDO À MEDIR
C8: % | D8: Qtde | E8: VALOR UNITÁRIO | F8: VALOR TOTAL | G8: TOTAL CONTRATUAL | H8: Qtde | I8: VALOR UNITÁRIO | J8: TOTAL DESTA MEDIÇÃO | K8: Qtde | L8: TOTAL ACUMULADO ANTERIOR | M8: SALDO | N8: %
A10: 1 | B10: DIÁRIA DE SERVENTE | C10: DIA | D10: 1 | E10: 323.73 | G10: =E10 -> 323.73 | H10: =Auxiliar!F68 -> 35 | I10: =+E10 -> 323.73 | J10: =+I10*H10 -> 11330.55 | K10: =+H10+'MED 03'!K10 -> 101 | L10: =+K10*I10 -> 32696.73
A11: 2 | B11: DIÁRIA DE MEIO-OFICIAL | C11: DIA | D11: 1 | E11: 443.63 | G11: =E11 -> 443.63 | H11: =Auxiliar!E68 -> 16 | I11: =+E11 -> 443.63 | J11: =+I11*H11 -> 7098.08 | K11: =+H11+'MED 03'!K11 -> 27 | L11: =+K11*I11 -> 11978.01
A12: 3 | B12: DIÁRIA DE PEDREIRO | C12: DIA | D12: 1 | E12: 477.42 | G12: =E12 -> 477.42 | H12: =Auxiliar!C68 -> 71 | I12: =+E12 -> 477.42 | J12: =+I12*H12 -> 33896.82 | K12: =+H12+'MED 03'!K12 -> 115 | L12: =+K12*I12 -> 54903.3
A13: 4 | B13: CONTRAPISO | C13: M2 | D13: 1 | E13: 39.93 | G13: =E13*D13 -> 39.93 | H13: 125.22 | I13: =+E13 -> 39.93 | J13: =+I13*H13 -> 5000.0346 | K13: =+H13 -> 125.22 | L13: =+J13 -> 5000.0346
A14: 5 | B14: REBOCO EXTERNO | C14: M2 | D14: 1 | E14: 45.98 | G14: =E14*D14 -> 45.98 | H14: =Auxiliar!M55 -> 123.36 | I14: =+E14 -> 45.98 | J14: =+I14*H14 -> 5672.0928 | K14: =+H14 -> 123.36 | L14: =+J14 -> 5672.0928
A15: 6 | B15: ESPALA VERTICAL | C15: M | D15: 1 | E15: =45.98/2 -> 22.99 | G15: =E15*D15 -> 22.99 | H15: =Auxiliar!M56 -> 6.664 | I15: =+E15 -> 22.99 | J15: =+I15*H15 -> 153.20536 | K15: =+H15 -> 6.664 | L15: =+J15 -> 153.20536
A16: 7 | B16: CHAPISCO | C16: M2 | D16: 1 | E16: 12.1 | G16: =E16*D16 -> 12.1 | H16: =Auxiliar!M57 -> 13.6328 | I16: =+E16 -> 12.1 | J16: =+I16*H16 -> 164.95688 | K16: =+H16 -> 13.6328 | L16: =+J16 -> 164.95688
A17: 8 | B17: TALISACAMENTO | C17: M2 | D17: 1 | E17: 14.52 | G17: =E17*D17 -> 14.52 | H17: =Auxiliar!M58 -> 5.246 | I17: =+E17 -> 14.52 | J17: =+I17*H17 -> 76.17192 | K17: =+H17 -> 5.246 | L17: =+J17 -> 76.17192
G18: =SUM(G10:G17) -> 1380.3 | J18: =SUM(J10:J17) -> 63391.912 | K18: T. ACUM. ATUAL | M18: =+SUM(L10:L17) -> 110644.5
B20: FATURAMENTO DIRETO | G20: =J18 -> 63391.912 | H20: RETENÇÃO CONTRATUAL - 5% | K20: RETENÇÃO IMPOSTOS
A21: ITEM | B21: FORNECEDOR/PRODUTO | C21: NF/QUANTIDADE | G21: VALOR | H21: ACUMULADA, INC. ESTA | J21: =+J26+'MED 02'!J17 -> 6884.3116
A22: 1 | B22: LUVA NITRILON | C22: 7 | E22: =9.38*C22 -> 65.66
A23: 2 | B23: OCULOS DE PROTEÇÃO | C23: 6 | E23: =6.5*C23 -> 39
A24: 3 | B24: BOTA PVC | C24: 2 | E24: =62*C24 -> 124
A25: 4 | B25: CAPACETE | E25: =57.99*C25 -> 0
E26: VALOR FAT. DIRETO | G26: =+SUM(E22:G25) -> 228.66 | H26: VALOR RETENÇÃO TÉCNICA | J26: =G28*0.05 -> 3158.1626 | K26: VALOR RETENÇÃO IMPOSTOS | M26: =M24 -> 0
B28: FARKAS CONSTRUTORA | E28: VALOR - FAT. DIRETO | G28: =G20-G26 -> 63163.252 | H28: VALOR - RETENÇÃO | J28: =G28-J26 -> 60005.089 | K28: VALOR NF A SER EMITIDA | M28: =+J28-M26 -> 60005.089

Sheet MED 05
D1: OBRA: FKR-018 - RIL
D2: FORNECEDOR: | G2: MBRUM CONSTRUÇÕES LTDA
D3: PLANILHA DE MEDIÇÃO DE SERVIÇOS - CONTRATUAL
B5: =G2 -> MBRUM CONSTRUÇÕES LTDA | H5: PERÍODO MEDIÇÃO | K5: BM-Nº | N5: 5
B6: =D1 -> OBRA: FKR-018 - RIL | H6: DE 08/04/2026 a 22/04/2026 | K6: VENCIMENTO | N6: 30/04/2026
A7: ITEM | B7: 1BN | C7: CONTRATUAL | H7: ESTA MEDIÇÃO | K7: ACUMULADO ATUAL | M7: SALDO À MEDIR
C8: % | D8: Qtde | E8: VALOR UNITÁRIO | F8: VALOR TOTAL | G8: TOTAL CONTRATUAL | H8: Qtde | I8: VALOR UNITÁRIO | J8: TOTAL DESTA MEDIÇÃO | K8: Qtde | L8: TOTAL ACUMULADO ANTERIOR | M8: SALDO | N8: %
A10: 1 | B10: DIÁRIA DE SERVENTE | C10: DIA | D10: 1 | E10: 323.73 | G10: =E10 -> 323.73 | H10: =Auxiliar!F68 -> 35 | I10: =+E10 -> 323.73 | J10: =+I10*H10 -> 11330.55 | K10: =+H10+'MED 04'!K10 -> 136 | L10: =+K10*I10 -> 44027.28
A11: 2 | B11: DIÁRIA DE MEIO-OFICIAL | C11: DIA | D11: 1 | E11: 443.63 | G11: =E11 -> 443.63 | H11: =Auxiliar!E68 -> 16 | I11: =+E11 -> 443.63 | J11: =+I11*H11 -> 7098.08 | K11: =+H11+'MED 04'!K11 -> 43 | L11: =+K11*I11 -> 19076.09
A12: 3 | B12: DIÁRIA DE PEDREIRO | C12: DIA | D12: 1 | E12: 477.42 | G12: =E12 -> 477.42 | H12: =Auxiliar!C68 -> 71 | I12: =+E12 -> 477.42 | J12: =+I12*H12 -> 33896.82 | K12: =+H12+'MED 04'!K12 -> 186 | L12: =+K12*I12 -> 88800.12
A13: 4 | B13: CONTRAPISO | C13: M2 | D13: 1 | E13: 39.93 | G13: =E13*D13 -> 39.93 | H13: =Auxiliar!M55 -> 123.36 | I13: =+E13 -> 39.93 | J13: =+I13*H13 -> 4925.7648 | K13: =+H13+'MED 04'!K13 -> 248.58 | L13: =+K13*I13 -> 9925.7994
A14: 5 | B14: ALVENARIA | C14: M2 | D14: 1 | E14: 45.98 | G14: =E14*D14 -> 45.98 | H14: =Auxiliar!M56 -> 6.664 | I14: =+E14 -> 45.98 | J14: =+I14*H14 -> 306.41072 | K14: =+H14 -> 6.664 | L14: =+K14*I14 -> 306.41072
A15: 6 | B15: CHAPISCO | C15: M | D15: 1 | E15: 12.1 | G15: =E15*D15 -> 12.1 | H15: =Auxiliar!M57 -> 13.6328 | I15: =+E15 -> 12.1 | J15: =+I15*H15 -> 164.95688 | K15: =+H15+'MED 04'!K16 -> 27.2656 | L15: =+K15*I15 -> 329.91376
A16: 7 | B16: CHAPISCO COLANTE | C16: M2 | D16: 1 | E16: 9.8 | G16: =E16*D16 -> 9.8 | H16: =Auxiliar!M58 -> 5.246 | I16: =+E16 -> 9.8 | J16: =+I16*H16 -> 51.4108 | K16: =+H16 -> 5.246 | L16: =+K16*I16 -> 51.4108
G17: =SUM(G10:G16) -> 1352.59 | J17: =SUM(J10:J16) -> 57773.993 | K17: T. ACUM. ATUAL | M17: =+SUM(L10:L16) -> 162517.02
B19: FATURAMENTO DIRETO | G19: =J17 -> 57773.993 | H19: RETENÇÃO CONTRATUAL - 5% | K19: RETENÇÃO IMPOSTOS
A20: ITEM | B20: FORNECEDOR/PRODUTO | C20: NF/QUANTIDADE | G20: VALOR | H20: ACUMULADA, INC. ESTA | J20: =+J25+'MED 04'!J21 -> 9756.6912
A21: 1 | B21: LUVA NITRILON | C21: 10 | E21: =9.38*C21 -> 93.8
A22: 2 | B22: OCULOS DE PROTEÇÃO | C22: 4 | E22: =6.5*C22 -> 26
A23: 3 | B23: BOTA PVC | C23: 3 | E23: =62*C23 -> 186 | Q23: =M27-50001.19 -> 4574.0235
A24: 4 | B24: CADEADO | C24: 2 | E24: =10.3*C24 -> 20.6
E25: VALOR FAT. DIRETO | G25: =+SUM(E21:G24) -> 326.4 | H25: VALOR RETENÇÃO TÉCNICA | J25: =G27*0.05 -> 2872.3797 | K25: VALOR RETENÇÃO IMPOSTOS | M25: =M23 -> 0
B27: FARKAS CONSTRUTORA | E27: VALOR - FAT. DIRETO | G27: =G19-G25 -> 57447.593 | H27: VALOR - RETENÇÃO | J27: =G27-J25 -> 54575.214 | K27: VALOR NF A SER EMITIDA | M27: =+J27-M25 -> 54575.214

Sheet Auxiliar
B2: DIÁRIAS MBRUM-28/02
C4: OFICIAL | D4: CARPINTEIRO | E4: 1/2 OFICIAL | F4: AJUDANTE
B5: 46056
B6: 46057
B7: 46058
B8: 46059
B9: 46062 | C9: 2 | F9: 1
B10: 46063 | C10: 2 | F10: 1
B11: 46064 | C11: 4 | E11: 1 | F11: 3
B12: 46065 | C12: 4 | F12: 4
B13: 46066 | C13: 4 | E13: 1 | F13: 4
B14: 46069 | E14: 1
B15: 46070
B16: 46071 | C16: 4 | E16: 1 | F16: 2
B17: 46072 | C17: 4 | E17: 1 | F17: 3
B18: 46073 | C18: 4 | E18: 1 | F18: 4
B19: 46076 | C19: 4 | E19: 1 | F19: 6
B20: 46077 | C20: 3 | E20: 1 | F20: 5
B21: TOTAL | C21: =SUM(C5:C20) -> 35 | D21: =SUM(D5:D20) -> 0 | E21: =SUM(E5:E20) -> 8 | F21: =SUM(F5:F20) -> 33
B23: DIÁRIAS MBRUM - 24/02 a 06/03
C25: OFICIAL | D25: CARPINTEIRO | E25: 1/2 OFICIAL | F25: AJUDANTE
B26: 46077 | C26: 4 | E26: 2 | F26: 6
B27: 46078 | C27: 7 | F27: 3
B28: 46079 | C28: 6 | E28: 1 | F28: 4
B29: 46080 | C29: 7 | E29: 1 | F29: 5
B30: 46083 | C30: 5 | E30: 1 | F30: 6
B31: 46084 | C31: 4 | E31: 1 | F31: 6
B32: 46085 | C32: 2 | E32: 1 | F32: 6
B33: 46086 | C33: 3 | E33: 1 | F33: 7
B34: 46087 | C34: 4 | E34: 1 | F34: 7
B35: RETROATIVO | C35: 5 | E35: 7 | F35: 2
B36: TOTAL | C36: =SUM(C26:C35) -> 47 | D36: =SUM(D26:D34) -> 0 | E36: =SUM(E26:E35) -> 16 | F36: =SUM(F26:F35) -> 52
B38: DIÁRIAS MBRUM - 09/03 a 23/03
C40: OFICIAL | D40: CARPINTEIRO | E40: 1/2 OFICIAL | F40: AJUDANTE
B41: 46090 | C41: 5 | E41: 1 | F41: 7 | K41: =4+4+5 -> 13
B42: 46091 | C42: 5 | E42: 1 | F42: 6 | J42: =13/3 -> 4.3333333
B43: 46092 | C43: 4 | E43: 1 | F43: 7
B44: 46093 | C44: 6 | E44: 1 | F44: 5
B45: 46094 | C45: 3 | E45: 1 | F45: 5
B46: 46097 | C46: 4 | E46: 1 | F46: 5
...
