Workbook

Sheet MED 01
D1: OBRA: FKR-018 - RIL
D2: FORNECEDOR: | G2: TRIUNO INSTALAÇÕES LTDA
D3: PLANILHA DE MEDIÇÃO DE SERVIÇOS - CONTRATUAL
B5: =G2 -> TRIUNO INSTALAÇÕES LTDA | H5: PERÍODO MEDIÇÃO | K5: BM-Nº | N5: 1
B6: =D1 -> OBRA: FKR-018 - RIL | H6: DE 05/02/2026 a 23/02/2026 | K6: VENCIMENTO | N6: 01/03/2026
A7: ITEM | B7: 1BN | C7: CONTRATUAL | H7: ESTA MEDIÇÃO | K7: ACUMULADO ATUAL | M7: SALDO À MEDIR
C8: % | D8: Qtde | E8: VALOR UNITÁRIO | F8: VALOR TOTAL | G8: TOTAL CONTRATUAL | H8: Qtde | J8: TOTAL DESTA MEDIÇÃO | K8: Qtde | L8: TOTAL ACUMULADO ANTERIOR | M8: SALDO | N8: %
I9: VALOR UNITÁRIO
A10: 1 | B10: DIÁRIA DA DUPLA | C10: DIA | D10: 1 | E10: 1450 | G10: =E10 -> 1450 | H10: 11 | I10: =+E10 -> 1450 | J10: =+I10*H10 -> 15950 | K10: =+H10 -> 11 | L10: =+J10 -> 15950
A11: 2 | B11: DIÁRIA DE AJUDANTE | C11: DIA | D11: 1 | E11: 450 | G11: =E11 -> 450 | H11: =Auxiliar!D20 -> 6 | I11: =+E11 -> 450 | J11: =+I11*H11 -> 2700 | K11: =+H11 -> 6 | L11: =+J11 -> 2700
G12: =E12 -> 0 | I12: =+E12 -> 0 | J12: =+I12*H12 -> 0 | K12: =+H12 -> 0 | L12: =+J12 -> 0
G14: =SUM(G10:G12) -> 1900 | J14: =SUM(J10:J12) -> 18650 | K14: T. ACUM. ATUAL | M14: =+SUM(L10:L12) -> 18650
B16: FATURAMENTO DIRETO | G16: =J14 -> 18650 | H16: RETENÇÃO CONTRATUAL - 5% | K16: RETENÇÃO IMPOSTOS
A17: ITEM | B17: FORNECEDOR/PRODUTO | C17: NF/QUANTIDADE | G17: VALOR | H17: ACUMULADA, INC. ESTA | J17: =+J23 -> 932.5
A18: 1
A19: 2
A20: 3
A21: 4
A22: 5
E23: VALOR FAT. DIRETO | G23: =+SUM(E18:G22) -> 0 | H23: VALOR RETENÇÃO TÉCNICA | J23: =G25*0.05 -> 932.5 | K23: VALOR RETENÇÃO IMPOSTOS | M23: =M21 -> 0
B25: FARKAS CONSTRUTORA | E25: VALOR - FAT. DIRETO | G25: =G16-G23 -> 18650 | H25: VALOR - RETENÇÃO | J25: =G25-J23 -> 17717.5 | K25: VALOR NF A SER EMITIDA | M25: =+J25-M23 -> 17717.5

Sheet MED 02
D1: OBRA: FKR-018 - RIL
D2: FORNECEDOR: | G2: TRIUNO INSTALAÇÕES LTDA
D3: PLANILHA DE MEDIÇÃO DE SERVIÇOS - CONTRATUAL
B5: =G2 -> TRIUNO INSTALAÇÕES LTDA | H5: PERÍODO MEDIÇÃO | K5: BM-Nº | N5: 1
B6: =D1 -> OBRA: FKR-018 - RIL | H6: DE 05/02/2026 a 23/02/2026 | K6: VENCIMENTO | N6: 01/03/2026
A7: ITEM | B7: 1BN | C7: CONTRATUAL | H7: ESTA MEDIÇÃO | K7: ACUMULADO ATUAL | M7: SALDO À MEDIR
C8: % | D8: Qtde | E8: VALOR UNITÁRIO | F8: VALOR TOTAL | G8: TOTAL CONTRATUAL | H8: Qtde | I8: VALOR UNITÁRIO | J8: TOTAL DESTA MEDIÇÃO | K8: Qtde | L8: TOTAL ACUMULADO ANTERIOR | M8: SALDO | N8: %
A10: 1 | B10: DIÁRIA DE ELETRICISTA | C10: DIA | D10: 1 | E10: 1000 | G10: =E10 -> 1000 | H10: =Auxiliar!C34 -> 9 | I10: =+E10 -> 1000 | J10: =+I10*H10 -> 9000 | K10: =+H10 -> 9 | L10: =+J10 -> 9000
A11: 2 | B11: DIÁRIA DE BOMBEIRO | C11: DIA | D11: 1 | E11: 1000 | G11: =E11 -> 1000 | H11: =Auxiliar!D34 -> 3.5 | I11: =+E11 -> 1000 | J11: =+I11*H11 -> 3500 | K11: =+H11 -> 3.5 | L11: =+J11 -> 3500
G12: =E12 -> 0 | I12: =+E12 -> 0 | J12: =+I12*H12 -> 0 | K12: =+H12 -> 0 | L12: =+J12 -> 0
G14: =SUM(G10:G12) -> 2000 | J14: =SUM(J10:J12) -> 12500 | K14: T. ACUM. ATUAL | M14: =+SUM(L10:L12) -> 12500
B16: FATURAMENTO DIRETO | G16: =J14 -> 12500 | H16: RETENÇÃO CONTRATUAL - 5% | K16: RETENÇÃO IMPOSTOS
A17: ITEM | B17: FORNECEDOR/PRODUTO | C17: NF/QUANTIDADE | G17: VALOR | H17: ACUMULADA, INC. ESTA | J17: =+J23+'MED 01'!J17 -> 1557.5
A18: 1
A19: 2
A20: 3
A21: 4
A22: 5
E23: VALOR FAT. DIRETO | G23: =+SUM(E18:G22) -> 0 | H23: VALOR RETENÇÃO TÉCNICA | J23: =G25*0.05 -> 625 | K23: VALOR RETENÇÃO IMPOSTOS | M23: =M21 -> 0
B25: FARKAS CONSTRUTORA | E25: VALOR - FAT. DIRETO | G25: =G16-G23 -> 12500 | H25: VALOR - RETENÇÃO | J25: =G25-J23 -> 11875 | K25: VALOR NF A SER EMITIDA | M25: =+J25-M23 -> 11875

Sheet MED 03
D1: OBRA: FKR-018 - RIL
D2: FORNECEDOR: | G2: TRIUNO INSTALAÇÕES LTDA
D3: PLANILHA DE MEDIÇÃO DE SERVIÇOS - CONTRATUAL
B5: =G2 -> TRIUNO INSTALAÇÕES LTDA | H5: PERÍODO MEDIÇÃO | K5: BM-Nº | N5: 3
B6: =D1 -> OBRA: FKR-018 - RIL | H6: DE 09/03/2026 a 23/03/2026 | K6: VENCIMENTO | N6: 30/03/2026
A7: ITEM | B7: 1BN | C7: CONTRATUAL | H7: ESTA MEDIÇÃO | K7: ACUMULADO ATUAL | M7: SALDO À MEDIR
C8: % | D8: Qtde | E8: VALOR UNITÁRIO | F8: VALOR TOTAL | G8: TOTAL CONTRATUAL | H8: Qtde | I8: VALOR UNITÁRIO | J8: TOTAL DESTA MEDIÇÃO | K8: Qtde | L8: TOTAL ACUMULADO ANTERIOR | M8: SALDO | N8: %
A10: 1 | B10: DIÁRIA DE ELETRICISTA | C10: DIA | D10: 1 | E10: 1000 | G10: =E10 -> 1000 | H10: =Auxiliar!D50 -> 7 | I10: =+E10 -> 1000 | J10: =+I10*H10 -> 7000 | K10: =+H10 -> 7 | L10: =+J10 -> 7000
A11: 2 | B11: DIÁRIA DE BOMBEIRO | C11: DIA | D11: 1 | E11: 1000 | G11: =E11 -> 1000 | H11: =Auxiliar!C50 -> 9 | I11: =+E11 -> 1000 | J11: =+I11*H11 -> 9000 | K11: =+H11 -> 9 | L11: =+J11 -> 9000
G12: =E12 -> 0 | I12: =+E12 -> 0 | J12: =+I12*H12 -> 0 | K12: =+H12 -> 0 | L12: =+J12 -> 0
G14: =SUM(G10:G12) -> 2000 | J14: =SUM(J10:J12) -> 16000 | K14: T. ACUM. ATUAL | M14: =+SUM(L10:L12) -> 16000
B16: FATURAMENTO DIRETO | G16: =J14 -> 16000 | H16: RETENÇÃO CONTRATUAL - 5% | K16: RETENÇÃO IMPOSTOS
A17: ITEM | B17: FORNECEDOR/PRODUTO | C17: NF/QUANTIDADE | G17: VALOR | H17: ACUMULADA, INC. ESTA | J17: =+J23+'MED 02'!J17 -> 2357.5
A18: 1
A19: 2
A20: 3
A21: 4
A22: 5
E23: VALOR FAT. DIRETO | G23: =+SUM(E18:G22) -> 0 | H23: VALOR RETENÇÃO TÉCNICA | J23: =G25*0.05 -> 800 | K23: VALOR RETENÇÃO IMPOSTOS | M23: =M21 -> 0
B25: FARKAS CONSTRUTORA | E25: VALOR - FAT. DIRETO | G25: =G16-G23 -> 16000 | H25: VALOR - RETENÇÃO | J25: =G25-J23 -> 15200 | K25: VALOR NF A SER EMITIDA | M25: =+J25-M23 -> 15200

Sheet MED 04
D1: OBRA: FKR-018 - RIL
D2: FORNECEDOR: | G2: TRIUNO INSTALAÇÕES LTDA
D3: PLANILHA DE MEDIÇÃO DE SERVIÇOS - CONTRATUAL
B5: =G2 -> TRIUNO INSTALAÇÕES LTDA | H5: PERÍODO MEDIÇÃO | K5: BM-Nº | N5: 4
B6: =D1 -> OBRA: FKR-018 - RIL | H6: DE 24/03/2026 a 07/04/2026 | K6: VENCIMENTO | N6: 15/04/2024
A7: ITEM | B7: 1BN | C7: CONTRATUAL | H7: ESTA MEDIÇÃO | K7: ACUMULADO ATUAL | M7: SALDO À MEDIR
C8: % | D8: Qtde | E8: VALOR UNITÁRIO | F8: VALOR TOTAL | G8: TOTAL CONTRATUAL | H8: Qtde | I8: VALOR UNITÁRIO | J8: TOTAL DESTA MEDIÇÃO | K8: Qtde | L8: TOTAL ACUMULADO ANTERIOR | M8: SALDO | N8: %
A10: 1 | B10: DIÁRIA DE ELETRICISTA | C10: DIA | D10: 1 | E10: 1000 | G10: =E10 -> 1000 | H10: =Auxiliar!C65 -> 2 | I10: =+E10 -> 1000 | J10: =+I10*H10 -> 2000 | K10: =+H10 -> 2 | L10: =+J10 -> 2000
G12: =SUM(G10:G10) -> 1000 | J12: =SUM(J10:J10) -> 2000 | K12: T. ACUM. ATUAL | M12: =+SUM(L10:L10) -> 2000
B14: FATURAMENTO DIRETO | G14: =J12 -> 2000 | H14: RETENÇÃO CONTRATUAL - 5% | K14: RETENÇÃO IMPOSTOS
A15: ITEM | B15: FORNECEDOR/PRODUTO | C15: NF/QUANTIDADE | G15: VALOR | H15: ACUMULADA, INC. ESTA | J15: =+J21+'MED 02'!J17 -> 1657.5
A16: 1
A17: 2
A18: 3
A19: 4
A20: 5
E21: VALOR FAT. DIRETO | G21: =+SUM(E16:G20) -> 0 | H21: VALOR RETENÇÃO TÉCNICA | J21: =G23*0.05 -> 100 | K21: VALOR RETENÇÃO IMPOSTOS | M21: =M19 -> 0
B23: FARKAS CONSTRUTORA | E23: VALOR - FAT. DIRETO | G23: =G14-G21 -> 2000 | H23: VALOR - RETENÇÃO | J23: =G23-J21 -> 1900 | K23: VALOR NF A SER EMITIDA | M23: =+J23-M21 -> 1900

Sheet Auxiliar
B2: DIÁRIAS TRIUNO-28/02
C4: OFICIAL + AJUDANTE | D4: AJUDANTE
B5: 46056
B6: 46057
B7: 46058 | C7: 2
B8: 46059 | C8: 2
B9: 46062 | C9: 2
B10: 46063 | C10: 2 | D10: 1
B11: 46064 | C11: 2 | D11: 1
B12: 46065 | C12: 2 | D12: 1
B13: 46066 | C13: 2 | D13: 1
B14: 46069
B15: 46070
B16: 46071 | C16: 2 | D16: 1
B17: 46072 | C17: 2 | D17: 1
B18: 46073 | C18: 2
B19: 46076 | C19: 2
B20: TOTAL | C20: =SUM(C5:C19) -> 22 | D20: =SUM(D5:D19) -> 6
B22: DIÁRIAS TRIUNO-24/02 A 06/03
C24: ELETRICISTA | D24: BOMBEIRO
B25: 46077 | C25: 1
B26: 46078 | C26: 1
B27: 46079 | C27: 1
B28: 46080 | C28: 1
B29: 46083 | C29: 1
B30: 46084 | C30: 1 | D30: 1
B31: 46085 | C31: 1 | D31: 1
B32: 46086 | C32: 1 | D32: 0.5
B33: 46087 | C33: 1 | D33: 1
B34: TOTAL | C34: =SUM(C25:C33) -> 9 | D34: =SUM(D25:D33) -> 3.5
B36: DIÁRIAS TRIUNO-09/03 A 23/03
C38: ELETRICISTA | D38: BOMBEIRO
B39: 46090 | C39: 1 | D39: 1
B40: 46091 | C40: 1 | D40: 1
B41: 46092 | C41: 1 | D41: 1
B42: 46093 | C42: 1 | D42: 1
B43: 46094 | C43: 1 | D43: 1
B44: 46097 | C44: 1 | D44: 1
B45: 46098 | C45: 1 | D45: 1
B46: 46099 | C46: 1
...
